Workbook

Sheet Executive Summary
A1: FDS v3.1.20 · Executive Schedule Summary (CANDIDATE)
A3: Metric | B3: Value | D3: Current gate / control | E3: Result
A4: As of | B4: 46287 | D4: G0 Design Freeze | E4: FULL PASS / Done
A5: Canonical version | B5: 3.1.19 RELEASED / 3.1.20 CANDIDATE | D5: G1 Target | E5: 46282
A6: Planning records | B6: =COUNTA(WBS!A4:A61) | D6: G2 Target | E6: 46286
A7: Tasks + CR | B7: =COUNTIF(WBS!E4:E61,"Task")+COUNTIF(WBS!E4:E61,"Change Request") | D7: G3 Target | E7: 46287
A8: Milestones | B8: =COUNTIF(WBS!E4:E61,"Milestone") | D8: ICR-D-NET-01-01 | E8: In Progress / Plan 09-21; actual pending
A9: All records / Milestone | B9: 67 / 67 | D9: CR-P1-ANS-01-01 | E9: Done / 2026-09-07
A11: Status | B11: Count | D11: Lead | E11: Records
A12: Done | B12: =COUNTIF(WBS!$G$4:$G$61,A12) | D12: 이권욱 | E12: =COUNTIF(WBS!$L$4:$L$61,D12)
A13: In Progress | B13: =COUNTIF(WBS!$G$4:$G$61,A13) | D13: 이하영 | E13: =COUNTIF(WBS!$L$4:$L$61,D13)
A14: In Review | B14: =COUNTIF(WBS!$G$4:$G$61,A14) | D14: 이재환 | E14: =COUNTIF(WBS!$L$4:$L$61,D14)
A15: To Do | B15: =COUNTIF(WBS!$G$4:$G$61,A15)
A18: Lead decisions / schedule alerts
A19: Priority | B19: Decision / Alert | C19: Impact | D19: Owner
A20: P0 | B20: ICR-D-NET-01-01 end date | C20: 계획 09-21; 실제 인수 미완료 | D20: 이권욱
A21: P0 | B21: Management return route | C21: monitor01/db01/harbor01/edge01 path evidence pending | D21: 이권욱
A22: P0 | B22: Phase 1 review calendar | C22: 09-22 오후 평일 Review 결정 Done; 실제 Review 별도 | D22: 이권욱
A23: P1 | B23: Phase 2 review calendar | C23: 2026-10-24 is Saturday; D24 pending | D23: 이권욱
A24: P1 | B24: Evidence placeholders | C24: Slides 11/12 are not completion evidence | D24: 이재환
A25: P0 | B25: Calendar history: 2026-09-04 | C25: 이력 보존; 현재 계획은 WBS/각 Gate 행 참조 | D25: 이권욱
A26: P0 | B26: Calendar history: 2026-09-08 | C26: P1-K8S/P1-HBR/P1-SEC Lead gap; ICR/P1-APP/P1-CICD support gap; no automatic rebaseline | D26: 이권욱
A27: P0 | B27: Gate targets: G1 09-17 / G2 09-21 / G3 09-22 | C27: Recommendation; evidence gates unchanged. Close 09-23 remains conditional.
A28: P1 | B28: P1 enhancements deferred | C28: MON-02 / DR-02 / HA-02: implementation dates TBD; handoff 09-23, replan decision 09-28.
A29: P0 | B29: Calendar history: 2026-09-10 | C29: Existing SEC window: 5→4 days. New window through 09-21: 10 available days; not remaining effort.

Sheet WBS
A1: FDS v3.1.20 · WBS (CANDIDATE)
A2: As of | B2: 46287 | C2: Canonical | D2: 3.1.19 RELEASED / 3.1.20 CANDIDATE | E2: Records | F2: =COUNTA(A4:A61)
A3: WBS ID | B3: Title | C3: Phase | D3: Category | E3: Type | F3: Priority | G3: Status | H3: Plan Start | I3: Plan End | J3: Calendar Days | K3: Lead Workdays | L3: Lead | M3: Support | N3: Dependencies / Decisions | O3: Risks | P3: Description / Exit Criteria | Q3: Schedule Note | R3: Source | S3: Schedule Health
A4: D-SEC-01 | B4: Security Design Scope / Approval Review | C4: Design | D4: Security / Governance | E4: Decision | F4: P0 | G4: Done | H4: 46260 | I4: 46266 | J4: =IF(OR(H4="",I4=""),"",I4-H4+1) | K4: =IF(OR(H4="",I4=""),"",NETWORKDAYS(H4,I4,'Sources & Change Log'!$J$2:$J$5)-COUNTIFS('Team Calendar'!$A$5:$A$12,L4,'Team Calendar'!$C$5:$C$12,">="&H4,'Team Calendar'!$C$5:$C$12,"<="&I4,'Team Calendar'!$F$5:$F$12,"Personal absence")) | L4: 이하영 | M4: 이권욱, 이재환 | N4: D17; D28 | O4: RISK-05; RISK-07 | P4: 승인권자 지정, D-SEC-01 검토 범위·산출물·Exit Criteria 승인, P1-SEC-01과의 경계 승인, 요구사항과 검증 증적 연결 후 Done 판정 | Q4: v3.1.14 최종 승인·정본 반영 완료. 구현은 P1-SEC-01로 이관. | R4: https://github.com/321Team/fds-project-baseline/issues/7 | S4: =IF(G4="Done","Done",IF(I4="","End TBD",IF(I4<'Executive Summary'!$B$4,"Overdue",IF(H4>'Executive Summary'!$B$4,"Upcoming","Active window"))))
A5: MS-G0-01 | B5: G0 Design Freeze | C5: Design | D5: Milestone / Design Freeze | E5: Milestone | F5: P0 | G5: Done | H5: 46260 | I5: 46266 | J5: =IF(OR(H5="",I5=""),"",I5-H5+1) | K5: =IF(OR(H5="",I5=""),"",NETWORKDAYS(H5,I5,'Sources & Change Log'!$J$2:$J$5)-COUNTIFS('Team Calendar'!$A$5:$A$12,L5,'Team Calendar'!$C$5:$C$12,">="&H5,'Team Calendar'!$C$5:$C$12,"<="&I5,'Team Calendar'!$F$5:$F$12,"Personal absence")) | L5: 이권욱 | M5: 이하영, 이재환 | N5: D17; D28; D32; D34; D35 | O5: RISK-05; RISK-07 | P5: D-ARC-01·D-NET-01·D-WBS-01·D-SEC-01 승인과 정본 Evidence를 확인하고 G0 FULL PASS 기록 확보 | Q5: G0 Design Freeze FULL PASS (2026-09-01). | R5: https://github.com/321Team/fds-project-baseline/issues/8 | S5: =IF(G5="Done","Done",IF(I5="","End TBD",IF(I5<'Executive Summary'!$B$4,"Overdue",IF(H5>'Executive Summary'!$B$4,"Upcoming","Active window"))))
A6: P1-LB-01 | B6: Kubernetes API Load Balancer | C6: Phase 1 | D6: Infrastructure / Load Balancer | E6: Task | F6: P0 | G6: In Progress | H6: 46261 | I6: 46282 | J6: =IF(OR(H6="",I6=""),"",I6-H6+1) | K6: =IF(OR(H6="",I6=""),"",NETWORKDAYS(H6,I6,'Sources & Change Log'!$J$2:$J$5)-COUNTIFS('Team Calendar'!$A$5:$A$12,L6,'Team Calendar'!$C$5:$C$12,">="&H6,'Team Calendar'!$C$5:$C$12,"<="&I6,'Team Calendar'!$F$5:$F$12,"Personal absence")) | L6: 이권욱 | M6: 이하영 | N6: D02; D05; D27; D31; D34; D35 | O6: RISK-02; RISK-03; RISK-04 | P6: IF-11/IF-11A/IF-06A Source Allowlist, `.109:6443→.102~.104:6443` Stage A Listener/Handoff와 Stage B Backend Health/API/Failover Evidence | Q6: Stage B는 3CP API 기동 후 검증하며 09-17 G1 인수에 연결한다. 실제 상태·완료 판정은 유지한다. 세부 배정: Fast Track Plan 시트. | R6: https://github.com/321Team/fds-project-baseline/issues/9 | S6: =IF(G6="Done","Done",IF(I6="",IF(F6="P1","Deferred P1","End TBD"),IF(I6<'Executive Summary'!$B$4,"Overdue",IF(H6>'Executive Summary'!$B$4,"Upcoming","Active window"))))
A7: P1-K8S-01 | B7: kubeadm 3CP + 3Worker / Calico | C7: Phase 1 | D7: Kubernetes / Platform | E7: Task | F7: P0 | G7: In Progress | H7: 46261 | I7: 46282 | J7: =IF(OR(H7="",I7=""),"",I7-H7+1) | K7: =IF(OR(H7="",I7=""),"",NETWORKDAYS(H7,I7,'Sources & Change Log'!$J$2:$J$5)-COUNTIFS('Team Calendar'!$A$5:$A$12,L7,'Team Calendar'!$C$5:$C$12,">="&H7,'Team Calendar'!$C$5:$C$12,"<="&I7,'Team Calendar'!$F$5:$F$12,"Personal absence")) | L7: 이하영 | M7: 이권욱 | N7: D01; D02; D05; D27; D31; D34; D35 | O7: RISK-02; RISK-03; RISK-04; RISK-07; RISK-14 | P7: LB Stage A 확인, 6개 Node의 보호 공백 없는 firewalld→named HEP/GNP 전환, containerd/kubelet·SELinux·identity·Port Matrix, BGP Disabled+VXLANCrossSubnet Calico, 6/6 Ready, CoreDNS, static local PV Evidence | Q7: 09-11 CP1, 09-14 CP2/3·Worker, 09-15 NTP·Calico, 09-17 증적 인수를 조건부 목표로 둔다. 실제 상태·완료 판정은 유지한다. 세부 배정: Fast Track Plan 시트. | R7: https://github.com/321Team/fds-project-baseline/issues/10 | S7: =IF(G7="Done","Done",IF(I7="",IF(F7="P1","Deferred P1","End TBD"),IF(I7<'Executive Summary'!$B$4,"Overdue",IF(H7>'Executive Summary'!$B$4,"Upcoming","Active window"))))
A8: P1-DB-01 | B8: PostgreSQL External VM | C8: Phase 1 | D8: Data / Database | E8: Task | F8: P0 | G8: In Progress | H8: 46262 | I8: 46282 | J8: =IF(OR(H8="",I8=""),"",I8-H8+1) | K8: =IF(OR(H8="",I8=""),"",NETWORKDAYS(H8,I8,'Sources & Change Log'!$J$2:$J$5)-COUNTIFS('Team Calendar'!$A$5:$A$12,L8,'Team Calendar'!$C$5:$C$12,">="&H8,'Team Calendar'!$C$5:$C$12,"<="&I8,'Team Calendar'!$F$5:$F$12,"Personal absence")) | L8: 이재환 | M8: 이권욱 | N8: D04; D05 | O8: RISK-04; RISK-07; RISK-09 | P8: db01 10.1.93.55:5432 구축, Schema/Migration 적용, transaction-api 승인 Source 접속·저장·조회 및 접근차단 Evidence 확보 | Q8: 09-11 이재환의 고정 Source·Schema·검증/복구 절차 인계가 선행돼야 한다. 기존 Support 이권욱이 부재 중 검증을 지원하며 실제 인수 권한은 기존 통제를 따른다. 실제 상태·완료 판정은 유지한다. 세부 배정: Fast Track Plan 시트. | R8: https://github.com/321Team/fds-project-baseline/issues/11 | S8: =IF(G8="Done","Done",IF(I8="",IF(F8="P1","Deferred P1","End TBD"),IF(I8<'Executive Summary'!$B$4,"Overdue",IF(H8>'Executive Summary'!$B$4,"Upcoming","Active window"))))
A9: P1-DNS-01 | B9: Internal DNS Primary/Secondary | C9: Phase 1 | D9: DNS / Supporting Service | E9: Task | F9: P1 | G9: Done | H9: 46262 | I9: 46268 | J9: =IF(OR(H9="",I9=""),"",I9-H9+1) | K9: =IF(OR(H9="",I9=""),"",NETWORKDAYS(H9,I9,'Sources & Change Log'!$J$2:$J$5)-COUNTIFS('Team Calendar'!$A$5:$A$12,L9,'Team Calendar'!$C$5:$C$12,">="&H9,'Team Calendar'!$C$5:$C$12,"<="&I9,'Team Calendar'!$F$5:$F$12,"Personal absence")) | L9: 이권욱 | M9: 이하영 | N9: D08; D09; D34; D35 | O9: RISK-02; RISK-04; RISK-07 | P9: Primary/Secondary·TSIG·제한 Query/Recursion·Failover Evidence와 k8s-api-lb01 `.109` Resolver/ACL/IPSet 검증 및 Support Review 승인 | Q9: 기술 검증·Support Review·.109 ACL/Resolver/Failover Delta 확인 완료. 2026-09-03 Done 승인. | R9: https://github.com/321Team/fds-project-baseline/issues/12 | S9: =IF(G9="Done","Done",IF(I9="","End TBD",IF(I9<'Executive Summary'!$B$4,"Overdue",IF(H9>'Executive Summary'!$B$4,"Upcoming","Active window"))))
A10: P1-HBR-01 | B10: Harbor / Trivy Registry | C10: Phase 1 | D10: Registry / Supply Chain | E10: Task | F10: P0 | G10: In Progress | H10: 46265 | I10: 46282 | J10: =IF(OR(H10="",I10=""),"",I10-H10+1) | K10: =IF(OR(H10="",I10=""),"",NETWORKDAYS(H10,I10,'Sources & Change Log'!$J$2:$J$5)-COUNTIFS('Team Calendar'!$A$5:$A$12,L10,'Team Calendar'!$C$5:$C$12,">="&H10,'Team Calendar'!$C$5:$C$12,"<="&I10,'Team Calendar'!$F$5:$F$12,"Personal absence")) | L10: 이하영 | M10: 이권욱 | N10: D04; D17; D19; D35 | O10: RISK-04; RISK-06; RISK-07 | P10: harbor01 `.54:443`, Private CA Trust, 최소권한 Robot Account, IF-09 Runner Push·IF-10 Worker Pull/Pod Start, 비승인 Push/Pull DENY, Trivy/Digest/Evidence PASS | Q10: Harbor 준비는 CP 후속과 병행하고 09-16 CI Scan Digest까지 4/4 대조 후 09-17 인수 목표다. 실제 상태·완료 판정은 유지한다. 세부 배정: Fast Track Plan 시트. | R10: https://github.com/321Team/fds-project-baseline/issues/13 | S10: =IF(G10="Done","Done",IF(I10="",IF(F10="P1","Deferred P1","End TBD"),IF(I10<'Executive Summary'!$B$4,"Overdue",IF(H10>'Executive Summary'!$B$4,"Upcoming","Active window"))))
A11: ICR-D-NET-01-01 | B11: Kubernetes Node Host Firewall / Monitoring Route | C11: Phase 1 | D11: Network / Interface Change Control | E11: Change Request | F11: P0 | G11: In Progress | H11: 46266 | I11: 46286 | J11: =IF(OR(H11="",I11=""),"",I11-H11+1) | K11: =IF(OR(H11="",I11=""),"",NETWORKDAYS(H11,I11,'Sources & Change Log'!$J$2:$J$5)-COUNTIFS('Team Calendar'!$A$5:$A$12,L11,'Team Calendar'!$C$5:$C$12,">="&H11,'Team Calendar'!$C$5:$C$12,"<="&I11,'Team Calendar'!$F$5:$F$12,"Personal absence")) | L11: 이권욱 | M11: 이하영, 이재환 | N11: D17; D18; D33; D34; D35 | O11: RISK-04; RISK-07 | P11: Kubernetes 6개 Node의 보호 공백 없는 firewalld→Calico named HEP/GNP 전환, 30080/9100/10250 최소 허용, 관리망 반환 경로와 IF-06B 정합화, Positive/Negative/Regression/Reboot/Rollback 및 무결성 Evidence 완료 | Q11: 09-21은 권장 Plan End이며 실제 종료일 확정이나 AC 완료가 아니다. 기존 End TBD 이력은 보존한다. CP→Worker·NTP·IF-16을 먼저, IF-06B·Negative/Reboot/Rollback·보호 인계를 후속 검증한다. 실제 상태·완료 판정은 유지한다. 세부 배정: Fast Track Plan 시트. | R11: https://github.com/321Team/fds-project-baseline/issues/14 | S11: =IF(G11="Done","Done",IF(I11="",IF(F11="P1","Deferred P1","End TBD"),IF(I11<'Executive Summary'!$B$4,"Overdue",IF(H11>'Executive Summary'!$B$4,"Upcoming","Active window"))))
A12: CR-P1-ANS-01-01 | B12: Ansible Kubernetes Node DNS Resolver 변경 | C12: Phase 1 | D12: Automation / DNS Client | E12: Change Request | F12: P1 | G12: Done | H12: 46269 | I12: 46272 | J12: =IF(OR(H12="",I12=""),"",I12-H12+1) | K12: =IF(OR(H12="",I12=""),"",NETWORKDAYS(H12,I12,'Sources & Change Log'!$J$2:$J$5)-COUNTIFS('Team Calendar'!$A$5:$A$12,L12,'Team Calendar'!$C$5:$C$12,">="&H12,'Team Calendar'!$C$5:$C$12,"<="&I12,'Team Calendar'!$F$5:$F$12,"Personal absence")) | L12: 이권욱 | M12: 이하영 | N12: D08; D09; D34; D35 | O12: RISK-02; RISK-04; RISK-07 | P12: Kubernetes 6개 Node의 DNS 전환, 검색 도메인·API FQDN/Short Name·외부 DNS·직접 질의·서비스 회귀·멱등성·Rollback·Evidence 무결성 및 Support Review 완료 | Q12: 2026-09-07 Runtime·멱등성·회귀·Rollback·무결성 증적과 이하영 승인 리뷰를 완료하고 이권욱 수동 승인으로 PR #1을 병합했다. GitHub Actions 실행은 0건이므로 CI PASS로 기록하지 않는다. v3.1.17의 `In Review` 표시는 발행 시점 스냅샷이며 다음 정본에서 `Done`으로 동기화한다. | R12: https://github.com/321Team/fds-project-baseline/issues/58 | S12: =IF(G12="Done","Done",IF(I12="","End TBD",IF(I12<'Executive Summary'!$B$4,"Overdue",IF(H12>'Executive Summary'!$B$4,"Upcoming","Active window"))))
A13: P1-APP-01 | B13: transaction-api / fds-engine | C13: Phase 1 | D13: Application / MSA | E13: Task | F13: P0 | G13: In Progress | H13: 46266 | I13: 46283 | J13: =IF(OR(H13="",I13=""),"",I13-H13+1) | K13: =IF(OR(H13="",I13=""),"",NETWORKDAYS(H13,I13,'Sources & Change Log'!$J$2:$J$5)-COUNTIFS('Team Calendar'!$A$5:$A$12,L13,'Team Calendar'!$C$5:$C$12,">="&H13,'Team Calendar'!$C$5:$C$12,"<="&I13,'Team Calendar'!$F$5:$F$12,"Personal absence")) | L13: 이재환 | M13: 이하영 | N13: D03; D04; D18; D27; D31; D34 | O13: RISK-07; RISK-09 | P13: 2개 Deployment/Service, 업무 8000/8001·metrics 9091/9090, `/livez`·`/readyz`, DB/FDS 장애정책, Resource, local endpoint topology, Contract/E2E Evidence | Q13: 09-11 인계 및 사전 검증, 09-18 복귀 후 정본 Runtime 통합. 휴가 중 미승인 업무 계약·Schema 변경은 중단한다. 실제 상태·완료 판정은 유지한다. 세부 배정: Fast Track Plan 시트. | R13: https://github.com/321Team/fds-project-baseline/issues/15 | S13: =IF(G13="Done","Done",IF(I13="",IF(F13="P1","Deferred P1","End TBD"),IF(I13<'Executive Summary'!$B$4,"Overdue",IF(H13>'Executive Summary'!$B$4,"Upcoming","Active window"))))
A14: P1-CICD-01 | B14: GitHub Actions / Self-hosted Runner Delivery | C14: Phase 1 | D14: CI/CD / Supply Chain | E14: Task | F14: P0 | G14: In Progress | H14: 46266 | I14: 46283 | J14: =IF(OR(H14="",I14=""),"",I14-H14+1) | K14: =IF(OR(H14="",I14=""),"",NETWORKDAYS(H14,I14,'Sources & Change Log'!$J$2:$J$5)-COUNTIFS('Team Calendar'!$A$5:$A$12,L14,'Team Calendar'!$C$5:$C$12,">="&H14,'Team Calendar'!$C$5:$C$12,"<="&I14,'Team Calendar'!$F$5:$F$12,"Personal absence")) | L14: 이권욱 | M14: 이하영 | N14: D03; D04; D19; D34; D35 | O14: RISK-06; RISK-08 | P14: GitHub→Runner→Test→Build→Trivy→Harbor→Kubernetes Deploy→Health/E2E 흐름과 실패 시 Deploy 차단 Evidence 확보; 승인 Digest와 이전 Digest 복구 추적 | Q14: Runner/Workflow·Negative Gate 준비를 플랫폼 구축과 병행하고 승인된 플랫폼·Harbor가 준비된 뒤 배포한다. 실제 상태·완료 판정은 유지한다. 세부 배정: Fast Track Plan 시트. | R14: https://github.com/321Team/fds-project-baseline/issues/16 | S14: =IF(G14="Done","Done",IF(I14="",IF(F14="P1","Deferred P1","End TBD"),IF(I14<'Executive Summary'!$B$4,"Overdue",IF(H14>'Executive Summary'!$B$4,"Upcoming","Active window"))))
A15: P1-MON-01 | B15: Kubernetes-Integrated Hybrid Monitoring 구축 및 검증 | C15: Phase 1 | D15: Monitoring / Observability | E15: Task | F15: P0 | G15: In Progress | H15: 46272 | I15: 46283 | J15: =IF(OR(H15="",I15=""),"",I15-H15+1) | K15: =IF(OR(H15="",I15=""),"",NETWORKDAYS(H15,I15,'Sources & Change Log'!$J$2:$J$5)-COUNTIFS('Team Calendar'!$A$5:$A$12,L15,'Team Calendar'!$C$5:$C$12,">="&H15,'Team Calendar'!$C$5:$C$12,"<="&I15,'Team Calendar'!$F$5:$F$12,"Personal absence")) | L15: 이재환 | M15: 이권욱 | N15: D05; D14; D17; D19; D33; D34 | O15: RISK-04; RISK-07 | P15: Hybrid Monitoring의 Runtime Acceptance 14개와 필수 보조통제 2개, 구축·복구·Rollback Runbook 및 Support Review 증적 확보 | Q15: 09-11 Monitoring 인계, 부재 중 기존 Support의 준비·구현, 09-18 복귀 후 14개 AC+2개 보조통제 검증을 목표로 한다. 실제 상태·완료 판정은 유지한다. 세부 배정: Fast Track Plan 시트. | R15: https://github.com/321Team/fds-project-baseline/issues/17 | S15: =IF(G15="Done","Done",IF(I15="",IF(F15="P1","Deferred P1","End TBD"),IF(I15<'Executive Summary'!$B$4,"Overdue",IF(H15>'Executive Summary'!$B$4,"Upcoming","Active window"))))
A16: MS-G1-01 | B16: G1 Infrastructure Ready | C16: Phase 1 | D16: Milestone / Infrastructure | E16: Milestone | F16: P0 | G16: To Do | H16: 46282 | I16: 46282 | J16: =IF(OR(H16="",I16=""),"",I16-H16+1) | K16: =IF(OR(H16="",I16=""),"",NETWORKDAYS(H16,I16,'Sources & Change Log'!$J$2:$J$5)-COUNTIFS('Team Calendar'!$A$5:$A$12,L16,'Team Calendar'!$C$5:$C$12,">="&H16,'Team Calendar'!$C$5:$C$12,"<="&I16,'Team Calendar'!$F$5:$F$12,"Personal absence")) | L16: 이권욱 | M16: 이하영, 이재환 | N16: D19; D25; D27 | O16: RISK-02; RISK-03; RISK-04; RISK-06; RISK-07; RISK-08 | P16: CentOS/containerd, Ansible Inventory/SSH/멱등성, 3CP+3Worker, API LB/Calico, Harbor/Runner/PostgreSQL, Node Connectivity와 Push/Pull 준비도 승인 | Q16: 09-17 오후 조건부 인수 목표. 6대·API/LB·Calico·DB·Harbor·Runner 증적 미충족이면 PASS 불가. 실제 상태·완료 판정은 유지한다. 세부 배정: Fast Track Plan 시트. | R16: https://github.com/321Team/fds-project-baseline/issues/18 | S16: =IF(G16="Done","Done",IF(I16="",IF(F16="P1","Deferred P1","End TBD"),IF(I16<'Executive Summary'!$B$4,"Overdue",IF(H16>'Executive Summary'!$B$4,"Upcoming","Active window"))))
A17: P1-SEC-01 | B17: Kubernetes Security Controls | C17: Phase 1 | D17: Security / Kubernetes | E17: Task | F17: P0 | G17: In Progress | H17: 46269 | I17: 46286 | J17: =IF(OR(H17="",I17=""),"",I17-H17+1) | K17: =IF(OR(H17="",I17=""),"",NETWORKDAYS(H17,I17,'Sources & Change Log'!$J$2:$J$5)-COUNTIFS('Team Calendar'!$A$5:$A$12,L17,'Team Calendar'!$C$5:$C$12,">="&H17,'Team Calendar'!$C$5:$C$12,"<="&I17,'Team Calendar'!$F$5:$F$12,"Personal absence")) | L17: 이하영 | M17: 이권욱, 이재환 | N17: D12; D17; D18; D19; D27; D31; D34 | O17: RISK-06; RISK-07; RISK-08 | P17: PSA/SecurityContext/Default Deny/RBAC/HEP-GNP/Secretbox/LimitRange/Probe와 `.50/32→30080` 포함 Positive·Negative·Rollback Evidence PASS | Q17: 09-10 휴가 추가 후 기존 09-04~11 가용일은 4일. 권장 종료 09-21로 확장한 전체 계획창의 가용일은 10일이며 잔여 공수를 뜻하지 않는다. Runtime 검증은 플랫폼·앱 인수와 연계한다. 실제 상태·완료 판정은 유지한다. 세부 배정: Fast Track Plan 시트. | R17: https://github.com/321Team/fds-project-baseline/issues/19 | S17: =IF(G17="Done","Done",IF(I17="",IF(F17="P1","Deferred P1","End TBD"),IF(I17<'Executive Summary'!$B$4,"Overdue",IF(H17>'Executive Summary'!$B$4,"Upcoming","Active window"))))
A18: P1-E2E-01 | B18: Initial / Final E2E & Regression | C18: Phase 1 | D18: QA / Integration Test | E18: Task | F18: P0 | G18: To Do | H18: 46276 | I18: 46287 | J18: =IF(OR(H18="",I18=""),"",I18-H18+1) | K18: =IF(OR(H18="",I18=""),"",NETWORKDAYS(H18,I18,'Sources & Change Log'!$J$2:$J$5)-COUNTIFS('Team Calendar'!$A$5:$A$12,L18,'Team Calendar'!$C$5:$C$12,">="&H18,'Team Calendar'!$C$5:$C$12,"<="&I18,'Team Calendar'!$F$5:$F$12,"Personal absence")) | L18: 이재환 | M18: 이권욱, 이하영 | N18: D03; D05; D17; D18 | O18: RISK-05; RISK-07; RISK-09 | P18: Client→edge→transaction-api→fds-engine→PostgreSQL→Prometheus E2E, Rule·Negative·Regression PASS, Critical Issue 0 및 Evidence 승인 | Q18: 09-11은 케이스·명령·판정 기준 준비일, Runtime은 09-18 이후, 최종 회귀는 09-22 오전이다. 실제 상태·완료 판정은 유지한다. 세부 배정: Fast Track Plan 시트. | R18: https://github.com/321Team/fds-project-baseline/issues/20 | S18: =IF(G18="Done","Done",IF(I18="",IF(F18="P1","Deferred P1","End TBD"),IF(I18<'Executive Summary'!$B$4,"Overdue",IF(H18>'Executive Summary'!$B$4,"Upcoming","Active window"))))
A19: P1-DR-01 | B19: PostgreSQL Backup / Restore | C19: Phase 1 | D19: DR / Data Recovery | E19: Task | F19: P0 | G19: To Do | H19: 46276 | I19: 46286 | J19: =IF(OR(H19="",I19=""),"",I19-H19+1) | K19: =IF(OR(H19="",I19=""),"",NETWORKDAYS(H19,I19,'Sources & Change Log'!$J$2:$J$5)-COUNTIFS('Team Calendar'!$A$5:$A$12,L19,'Team Calendar'!$C$5:$C$12,">="&H19,'Team Calendar'!$C$5:$C$12,"<="&I19,'Team Calendar'!$F$5:$F$12,"Personal absence")) | L19: 이재환 | M19: 이권욱 | N19: D04 | O19: RISK-05; RISK-09 | P19: pg_dump Backup, 승인된 초기화/격리 환경 Restore, Row/Rule 결과 정합성 및 Restore 후 Final E2E PASS와 Runbook 확보 | Q19: 09-11 복구 절차·격리 대상 준비, 실제 Restore 및 후속 E2E는 09-21 오후 전용 창에서 수행한다. 실제 상태·완료 판정은 유지한다. 세부 배정: Fast Track Plan 시트. | R19: https://github.com/321Team/fds-project-baseline/issues/21 | S19: =IF(G19="Done","Done",IF(I19="",IF(F19="P1","Deferred P1","End TBD"),IF(I19<'Executive Summary'!$B$4,"Overdue",IF(H19>'Executive Summary'!$B$4,"Upcoming","Active window"))))
A20: P1-HA-01 | B20: Worker Drain Continuity | C20: Phase 1 | D20: HA / Resilience | E20: Task | F20: P0 | G20: To Do | H20: 46276 | I20: 46286 | J20: =IF(OR(H20="",I20=""),"",I20-H20+1) | K20: =IF(OR(H20="",I20=""),"",NETWORKDAYS(H20,I20,'Sources & Change Log'!$J$2:$J$5)-COUNTIFS('Team Calendar'!$A$5:$A$12,L20,'Team Calendar'!$C$5:$C$12,">="&H20,'Team Calendar'!$C$5:$C$12,"<="&I20,'Team Calendar'!$F$5:$F$12,"Personal absence")) | L20: 이재환 | M20: 이하영 | N20: D02; D03 | O20: RISK-03; RISK-05; RISK-07 | P20: FDS Replica 3개 Worker 분산, Worker Drain 중 승인된 서비스 지속 기준 충족, 복구·Uncordon 및 E2E Evidence 확보 | Q20: 09-11 Drain 케이스 준비, 3Worker 및 서비스 분산 확인 후 09-21 오전 전용 창에서 수행한다. 실제 상태·완료 판정은 유지한다. 세부 배정: Fast Track Plan 시트. | R20: https://github.com/321Team/fds-project-baseline/issues/22 | S20: =IF(G20="Done","Done",IF(I20="",IF(F20="P1","Deferred P1","End TBD"),IF(I20<'Executive Summary'!$B$4,"Overdue",IF(H20>'Executive Summary'!$B$4,"Upcoming","Active window"))))
A21: MS-G2-01 | B21: G2 Security / Feature Ready | C21: Phase 1 | D21: Milestone / Security & Feature | E21: Milestone | F21: P0 | G21: To Do | H21: 46286 | I21: 46286 | J21: =IF(OR(H21="",I21=""),"",I21-H21+1) | K21: =IF(OR(H21="",I21=""),"",NETWORKDAYS(H21,I21,'Sources & Change Log'!$J$2:$J$5)-COUNTIFS('Team Calendar'!$A$5:$A$12,L21,'Team Calendar'!$C$5:$C$12,">="&H21,'Team Calendar'!$C$5:$C$12,"<="&I21,'Team Calendar'!$F$5:$F$12,"Personal absence")) | L21: 이하영 | M21: 이권욱, 이재환 | N21: D17; D18; D19; D27 | O21: RISK-05; RISK-06; RISK-07; RISK-08; RISK-09 | P21: 2-Service MSA, DB 저장, Security P0, CI/CD, Monitoring, Initial E2E/Negative Test/Worker Drain 준비도를 승인 | Q21: 09-21 오후 종료 시점 목표. 앱/보안/CI/Monitoring·초기 E2E/Negative/Drain 준비도와 해당 증적이 선행한다. 실제 상태·완료 판정은 유지한다. 세부 배정: Fast Track Plan 시트. | R21: https://github.com/321Team/fds-project-baseline/issues/23 | S21: =IF(G21="Done","Done",IF(I21="",IF(F21="P1","Deferred P1","End TBD"),IF(I21<'Executive Summary'!$B$4,"Overdue",IF(H21>'Executive Summary'!$B$4,"Upcoming","Active window"))))
A22: P1-DOC-01 | B22: Architecture / Test / Runbook Freeze | C22: Phase 1 | D22: PMO / Documentation | E22: Task | F22: P0 | G22: To Do | H22: 46276 | I22: 46287 | J22: =IF(OR(H22="",I22=""),"",I22-H22+1) | K22: =IF(OR(H22="",I22=""),"",NETWORKDAYS(H22,I22,'Sources & Change Log'!$J$2:$J$5)-COUNTIFS('Team Calendar'!$A$5:$A$12,L22,'Team Calendar'!$C$5:$C$12,">="&H22,'Team Calendar'!$C$5:$C$12,"<="&I22,'Team Calendar'!$F$5:$F$12,"Personal absence")) | L22: 이권욱 | M22: 이하영, 이재환 | N22: D12; D20; D25 | O22: RISK-05; RISK-13 | P22: As-built Architecture, Test/Evidence Index, 구축·운영·복구 Runbook, P1 미완료 Known Issue의 풀네임 Owner·Due, Version/Source 및 Review 재현성 승인 | Q22: 구축 시 증적·Runbook을 병행 축적하고 09-22 오전 Final Evidence와 함께 동결한다. 실제 상태·완료 판정은 유지한다. 세부 배정: Fast Track Plan 시트. | R22: https://github.com/321Team/fds-project-baseline/issues/24 | S22: =IF(G22="Done","Done",IF(I22="",IF(F22="P1","Deferred P1","End TBD"),IF(I22<'Executive Summary'!$B$4,"Overdue",IF(H22>'Executive Summary'!$B$4,"Upcoming","Active window"))))
A23: P1-MON-02 | B23: Dashboard / Alert Enhancement | C23: Phase 1 | D23: Monitoring / Observability | E23: Task | F23: P1 | G23: To Do | J23: =IF(OR(H23="",I23=""),"",I23-H23+1) | K23: =IF(OR(H23="",I23=""),"",NETWORKDAYS(H23,I23,'Sources & Change Log'!$J$2:$J$5)-COUNTIFS('Team Calendar'!$A$5:$A$12,L23,'Team Calendar'!$C$5:$C$12,">="&H23,'Team Calendar'!$C$5:$C$12,"<="&I23,'Team Calendar'!$F$5:$F$12,"Personal absence")) | L23: 이재환 | M23: 이권욱, 이하영 | N23: D25; D33 | O23: RISK-05; RISK-07; RISK-09; RISK-14 | P23: Prometheus 2 Replica·Alertmanager 3 Replica, PDB/TopologySpread, Dashboard/Alert·장기보존 고도화와 장애·복구·P0 회귀 Evidence 및 Review | Q23: P0 마감 보호를 위해 신규 구현을 유예하는 권장안이다. 기존 Lead·Type·Priority·AC·To Do는 유지한다. 09-23은 Known Issue/Owner 인계 기한, 09-28은 차기 착수·납기 결정 기한이며 구현 완료일은 TBD다. Phase 2 공수를 자동 배정하지 않는다. 실제 상태·완료 판정은 유지한다. 세부 배정: Fast Track Plan 시트. | R23: https://github.com/321Team/fds-project-baseline/issues/25 | S23: =IF(G23="Done","Done",IF(I23="",IF(F23="P1","Deferred P1","End TBD"),IF(I23<'Executive Summary'!$B$4,"Overdue",IF(H23>'Executive Summary'!$B$4,"Upcoming","Active window"))))
A24: P1-DR-02 | B24: Harbor / etcd Backup and Restore | C24: Phase 1 | D24: DR / Platform Recovery | E24: Task | F24: P1 | G24: To Do | J24: =IF(OR(H24="",I24=""),"",I24-H24+1) | K24: =IF(OR(H24="",I24=""),"",NETWORKDAYS(H24,I24,'Sources & Change Log'!$J$2:$J$5)-COUNTIFS('Team Calendar'!$A$5:$A$12,L24,'Team Calendar'!$C$5:$C$12,">="&H24,'Team Calendar'!$C$5:$C$12,"<="&I24,'Team Calendar'!$F$5:$F$12,"Personal absence")) | L24: 이하영 | M24: 이권욱, 이재환 | N24: D04; D25 | O24: RISK-05; RISK-06; RISK-08; RISK-14 | P24: Harbor Backup/Restore와 etcd Snapshot/Restore를 격리 대상에서 수행하고 무결성·복구·Runbook Evidence 확보 | Q24: P0 마감 보호를 위해 신규 구현을 유예하는 권장안이다. 기존 Lead·Type·Priority·AC·To Do는 유지한다. 09-23은 Known Issue/Owner 인계 기한, 09-28은 차기 착수·납기 결정 기한이며 구현 완료일은 TBD다. Phase 2 공수를 자동 배정하지 않는다. 실제 상태·완료 판정은 유지한다. 세부 배정: Fast Track Plan 시트. | R24: https://github.com/321Team/fds-project-baseline/issues/26 | S24: =IF(G24="Done","Done",IF(I24="",IF(F24="P1","Deferred P1","End TBD"),IF(I24<'Executive Summary'!$B$4,"Overdue",IF(H24>'Executive Summary'!$B$4,"Upcoming","Active window"))))
A25: P1-HA-02 | B25: Platform Resilience P1 Validation | C25: Phase 1 | D25: HA / Platform Resilience | E25: Task | F25: P1 | G25: To Do | J25: =IF(OR(H25="",I25=""),"",I25-H25+1) | K25: =IF(OR(H25="",I25=""),"",NETWORKDAYS(H25,I25,'Sources & Change Log'!$J$2:$J$5)-COUNTIFS('Team Calendar'!$A$5:$A$12,L25,'Team Calendar'!$C$5:$C$12,">="&H25,'Team Calendar'!$C$5:$C$12,"<="&I25,'Team Calendar'!$F$5:$F$12,"Personal absence")) | L25: 이하영 | M25: 이권욱, 이재환 | N25: D02; D25 | O25: RISK-03; RISK-05; RISK-07; RISK-14 | P25: Rolling Update, Control Plane 1대 장애, PDB 및 TopologySpreadConstraint 검증 결과와 복구 Evidence 확보 | Q25: P0 마감 보호를 위해 신규 구현을 유예하는 권장안이다. 기존 Lead·Type·Priority·AC·To Do는 유지한다. 09-23은 Known Issue/Owner 인계 기한, 09-28은 차기 착수·납기 결정 기한이며 구현 완료일은 TBD다. Phase 2 공수를 자동 배정하지 않는다. 실제 상태·완료 판정은 유지한다. 세부 배정: Fast Track Plan 시트. | R25: https://github.com/321Team/fds-project-baseline/issues/27 | S25: =IF(G25="Done","Done",IF(I25="",IF(F25="P1","Deferred P1","End TBD"),IF(I25<'Executive Summary'!$B$4,"Overdue",IF(H25>'Executive Summary'!$B$4,"Upcoming","Active window"))))
A26: DEC-CAL-P1-01 | B26: Phase 1 Weekend Review Decision | C26: Phase 1 | D26: Schedule / Governance | E26: Decision | F26: P0 | G26: Done | H26: 46276 | I26: 46276 | J26: =IF(OR(H26="",I26=""),"",I26-H26+1) | K26: =IF(OR(H26="",I26=""),"",NETWORKDAYS(H26,I26,'Sources & Change Log'!$J$2:$J$5)-COUNTIFS('Team Calendar'!$A$5:$A$12,L26,'Team Calendar'!$C$5:$C$12,">="&H26,'Team Calendar'!$C$5:$C$12,"<="&I26,'Team Calendar'!$F$5:$F$12,"Personal absence")) | L26: 이권욱 | M26: 이하영, 이재환 | N26: D20 | O26: RISK-05; RISK-13 | P26: 09-20 일요일 Review 유지 또는 영업일 재배치, 참석자·승인권자·시간·대체일을 확정하고 WBS/Calendar 동기화 | Q26: 2026-09-22 오후 평일 Review로 확정. 발표자료 담당자별 상세 일정에 이권욱·이하영·이재환 Review 역할이 배정되어 있고 #29/#30/#31 일정도 09-22로 정렬됨. 사용자 확인을 일정 결정 승인 근거로 삼아 Done 처리한다. 실제 G3 PASS·Review 결과·Phase 1 Close 승인은 #29/#30/#31에서 별도 판정한다. 교육장 주말 작업 0 원칙 유지. | R26: https://github.com/321Team/fds-project-baseline/issues/28 | S26: =IF(G26="Done","Done",IF(I26="",IF(F26="P1","Deferred P1","End TBD"),IF(I26<'Executive Summary'!$B$4,"Overdue",IF(H26>'Executive Summary'!$B$4,"Upcoming","Active window"))))
A27: MS-G3-01 | B27: G3 Review Ready | C27: Phase 1 | D27: Milestone / Review Readiness | E27: Milestone | F27: P0 | G27: To Do | H27: 46287 | I27: 46287 | J27: =IF(OR(H27="",I27=""),"",I27-H27+1) | K27: =IF(OR(H27="",I27=""),"",NETWORKDAYS(H27,I27,'Sources & Change Log'!$J$2:$J$5)-COUNTIFS('Team Calendar'!$A$5:$A$12,L27,'Team Calendar'!$C$5:$C$12,">="&H27,'Team Calendar'!$C$5:$C$12,"<="&I27,'Team Calendar'!$F$5:$F$12,"Personal absence")) | L27: 이권욱 | M27: 이하영, 이재환 | N27: D20 | O27: RISK-05; RISK-09; RISK-13 | P27: Final E2E/Regression, Worker Drain, PostgreSQL Restore, Critical Issue 0, Architecture/Test/Runbook 준비도를 승인 | Q27: 09-22 오전 최종 회귀·Drain·Restore 증적·Critical Issue 0과 산출물 동결이 모두 충족될 때 인수한다. 실제 상태·완료 판정은 유지한다. 세부 배정: Fast Track Plan 시트. | R27: https://github.com/321Team/fds-project-baseline/issues/29 | S27: =IF(G27="Done","Done",IF(I27="",IF(F27="P1","Deferred P1","End TBD"),IF(I27<'Executive Summary'!$B$4,"Overdue",IF(H27>'Executive Summary'!$B$4,"Upcoming","Active window"))))
A28: P1-REV-01 | B28: Phase 1 Review / Close Execution | C28: Phase 1 | D28: PMO / Review | E28: Task | F28: P0 | G28: To Do | H28: 46287 | I28: 46288 | J28: =IF(OR(H28="",I28=""),"",I28-H28+1) | K28: =IF(OR(H28="",I28=""),"",NETWORKDAYS(H28,I28,'Sources & Change Log'!$J$2:$J$5)-COUNTIFS('Team Calendar'!$A$5:$A$12,L28,'Team Calendar'!$C$5:$C$12,">="&H28,'Team Calendar'!$C$5:$C$12,"<="&I28,'Team Calendar'!$F$5:$F$12,"Personal absence")) | L28: 이권욱 | M28: 이하영, 이재환 | N28: D12; D20 | O28: RISK-05; RISK-13 | P28: G3 결과, Demo, P0 Evidence, Known Issue, P1 이관, Review Action을 승인하고 Phase 1 Close Sign-off 확보 | Q28: 09-22 오후 Review, 09-23 오전 보완·재시험, 오후 Close를 권장한다. 실제 상태·완료 판정은 유지한다. 세부 배정: Fast Track Plan 시트. | R28: https://github.com/321Team/fds-project-baseline/issues/30 | S28: =IF(G28="Done","Done",IF(I28="",IF(F28="P1","Deferred P1","End TBD"),IF(I28<'Executive Summary'!$B$4,"Overdue",IF(H28>'Executive Summary'!$B$4,"Upcoming","Active window"))))
A29: MS-P1-REVIEW-01 | B29: Phase 1 Review | C29: Phase 1 | D29: Milestone / Review | E29: Milestone | F29: P0 | G29: To Do | H29: 46287 | I29: 46287 | J29: =IF(OR(H29="",I29=""),"",I29-H29+1) | K29: =IF(OR(H29="",I29=""),"",NETWORKDAYS(H29,I29,'Sources & Change Log'!$J$2:$J$5)-COUNTIFS('Team Calendar'!$A$5:$A$12,L29,'Team Calendar'!$C$5:$C$12,">="&H29,'Team Calendar'!$C$5:$C$12,"<="&I29,'Team Calendar'!$F$5:$F$12,"Personal absence")) | L29: 이권욱 | M29: 이하영, 이재환 | N29: D20 | O29: RISK-05; RISK-13 | P29: 승인된 일정에 Demo/산출물/G3/Known Issue Review를 수행하고 Action 및 승인결과를 기록 | Q29: 기존 09-20 일요일 대신 09-22 화요일 오후. G3 통과와 참석자 확정이 필요하다. 실제 상태·완료 판정은 유지한다. 세부 배정: Fast Track Plan 시트. | R29: https://github.com/321Team/fds-project-baseline/issues/31 | S29: =IF(G29="Done","Done",IF(I29="",IF(F29="P1","Deferred P1","End TBD"),IF(I29<'Executive Summary'!$B$4,"Overdue",IF(H29>'Executive Summary'!$B$4,"Upcoming","Active window"))))
A30: MS-P1-CLOSE-01 | B30: Phase 1 Close | C30: Phase 1 | D30: Milestone / Close | E30: Milestone | F30: P0 | G30: To Do | H30: 46288 | I30: 46288 | J30: =IF(OR(H30="",I30=""),"",I30-H30+1) | K30: =IF(OR(H30="",I30=""),"",NETWORKDAYS(H30,I30,'Sources & Change Log'!$J$2:$J$5)-COUNTIFS('Team Calendar'!$A$5:$A$12,L30,'Team Calendar'!$C$5:$C$12,">="&H30,'Team Calendar'!$C$5:$C$12,"<="&I30,'Team Calendar'!$F$5:$F$12,"Personal absence")) | L30: 이권욱 | M30: 이하영, 이재환 | N30: D20 | O30: RISK-05; RISK-13 | P30: Review Action 처리, P0 승인, P1/Known Issue Owner·Due 이관 및 Phase 1 Close Sign-off 확보 | Q30: 09-24~09-25 비근무 전에 종결한다. | R30: https://github.com/321Team/fds-project-baseline/issues/32 | S30: =IF(G30="Done","Done",IF(I30="","End TBD",IF(I30<'Executive Summary'!$B$4,"Overdue",IF(H30>'Executive Summary'!$B$4,"Upcoming","Active window"))))
A31: MS-P2-START-01 | B31: Phase 2 Start | C31: Phase 2 | D31: Milestone / Start | E31: Milestone | F31: P0 | G31: To Do | H31: 46301 | I31: 46301 | J31: =IF(OR(H31="",I31=""),"",I31-H31+1) | K31: =IF(OR(H31="",I31=""),"",NETWORKDAYS(H31,I31,'Sources & Change Log'!$J$2:$J$5)-COUNTIFS('Team Calendar'!$A$5:$A$12,L31,'Team Calendar'!$C$5:$C$12,">="&H31,'Team Calendar'!$C$5:$C$12,"<="&I31,'Team Calendar'!$F$5:$F$12,"Personal absence")) | L31: 이권욱 | M31: 이하영, 이재환 | N31: D10; D21 | O31: RISK-05; RISK-10; RISK-11 | P31: Phase 1 Close, Phase 2 계정·권한·일정·P0 범위·OCI Go/No-Go 계획을 확인하고 착수 승인 | Q31: 09-24~09-25 비근무 후 첫 작업일에 착수한다. | R31: https://github.com/321Team/fds-project-baseline/issues/33 | S31: =IF(G31="Done","Done",IF(I31="","End TBD",IF(I31<'Executive Summary'!$B$4,"Overdue",IF(H31>'Executive Summary'!$B$4,"Upcoming","Active window"))))
A32: P2-ARC-01 | B32: Hybrid / OCI / AWS / ROSA Architecture Freeze | C32: Phase 2 | D32: Architecture / Hybrid Cloud | E32: Task | F32: P0 | G32: To Do | H32: 46301 | I32: 46301 | J32: =IF(OR(H32="",I32=""),"",I32-H32+1) | K32: =IF(OR(H32="",I32=""),"",NETWORKDAYS(H32,I32,'Sources & Change Log'!$J$2:$J$5)-COUNTIFS('Team Calendar'!$A$5:$A$12,L32,'Team Calendar'!$C$5:$C$12,">="&H32,'Team Calendar'!$C$5:$C$12,"<="&I32,'Team Calendar'!$F$5:$F$12,"Personal absence")) | L32: 이권욱 | M32: 이하영, 이재환 | N32: D10; D21; D22; D23; D25; D26 | O32: RISK-10; RISK-11; RISK-12; RISK-14; RISK-15 | P32: OCI Relay·AWS VPC/VPN·ROSA·On-Prem 연계 Architecture, Interface IF-17~IF-20, Security, Decision, Exit Criteria Freeze 승인 | Q32: MS-P2-START-01 직후 완료하며 Phase 2 모든 구현 티켓이 참조하는 Phase 2 OCI/AWS/ROSA Design의 권위 Source를 생성한다. | R32: https://github.com/321Team/fds-project-baseline/issues/34 | S32: =IF(G32="Done","Done",IF(I32="","End TBD",IF(I32<'Executive Summary'!$B$4,"Overdue",IF(H32>'Executive Summary'!$B$4,"Upcoming","Active window"))))
A33: P2-IAC-01 | B33: AWS / ROSA Terraform IaC | C33: Phase 2 | D33: Cloud / Terraform | E33: Task | F33: P0 | G33: To Do | H33: 46301 | I33: 46308 | J33: =IF(OR(H33="",I33=""),"",I33-H33+1) | K33: =IF(OR(H33="",I33=""),"",NETWORKDAYS(H33,I33,'Sources & Change Log'!$J$2:$J$5)-COUNTIFS('Team Calendar'!$A$5:$A$12,L33,'Team Calendar'!$C$5:$C$12,">="&H33,'Team Calendar'!$C$5:$C$12,"<="&I33,'Team Calendar'!$F$5:$F$12,"Personal absence")) | L33: 이권욱 | M33: 이하영 | N33: D10; D21; D25 | O33: RISK-10; RISK-11; RISK-12 | P33: AWS VPC 10.20.0.0/16, ROSA 선행 인프라와 IAM/OIDC 최소권한의 Terraform fmt/validate/plan/apply, State·Secret 통제 및 G4 Evidence 확보 | Q33: 10-05는 비근무일이다. OCI Go/No-Go 결과에 따라 VPN 입력과 경로를 갱신한다. | R33: https://github.com/321Team/fds-project-baseline/issues/35 | S33: =IF(G33="Done","Done",IF(I33="","End TBD",IF(I33<'Executive Summary'!$B$4,"Overdue",IF(H33>'Executive Summary'!$B$4,"Upcoming","Active window"))))
A34: P2-OCI-01 | B34: OCI Relay Go / No-Go | C34: Phase 2 | D34: Milestone / Hybrid Network | E34: Decision | F34: P0 | G34: To Do | H34: 46301 | I34: 46304 | J34: =IF(OR(H34="",I34=""),"",I34-H34+1) | K34: =IF(OR(H34="",I34=""),"",NETWORKDAYS(H34,I34,'Sources & Change Log'!$J$2:$J$5)-COUNTIFS('Team Calendar'!$A$5:$A$12,L34,'Team Calendar'!$C$5:$C$12,">="&H34,'Team Calendar'!$C$5:$C$12,"<="&I34,'Team Calendar'!$F$5:$F$12,"Personal absence")) | L34: 이권욱 | M34: 이하영 | N34: D10; D21 | O34: RISK-10; RISK-12 | P34: OCI Relay 가능성·권한·Public Endpoint·IPsec/NAT-T·Route를 검증하고 Primary 또는 승인 Fallback 경로를 선택 | Q34: 10-02 Go/No-Go를 넘기지 않는다. No-Go 시 Vendor Endpoint→AWS EC2+EIP Relay→Overlay 순으로 승인된 Fallback을 선택한다. | R34: https://github.com/321Team/fds-project-baseline/issues/36 | S34: =IF(G34="Done","Done",IF(I34="","End TBD",IF(I34<'Executive Summary'!$B$4,"Overdue",IF(H34>'Executive Summary'!$B$4,"Upcoming","Active window"))))
A35: P2-VPN-01 | B35: OCI Relay / AWS Site-to-Site VPN | C35: Phase 2 | D35: Hybrid Network / VPN | E35: Task | F35: P0 | G35: To Do | H35: 46303 | I35: 46308 | J35: =IF(OR(H35="",I35=""),"",I35-H35+1) | K35: =IF(OR(H35="",I35=""),"",NETWORKDAYS(H35,I35,'Sources & Change Log'!$J$2:$J$5)-COUNTIFS('Team Calendar'!$A$5:$A$12,L35,'Team Calendar'!$C$5:$C$12,">="&H35,'Team Calendar'!$C$5:$C$12,"<="&I35,'Team Calendar'!$F$5:$F$12,"Personal absence")) | L35: 이권욱 | M35: 이하영 | N35: D10; D21 | O35: RISK-04; RISK-10; RISK-12 | P35: 승인 Transit 경로의 Tunnel UP, On-Prem↔VPC Route, UDP 500/4500/IPsec, Source·승인 TCP Path 및 장애 Evidence 확보 | Q35: 10-05는 비근무일이다. OCI No-Go 시 D21에서 승인된 Fallback만 사용한다. | R35: https://github.com/321Team/fds-project-baseline/issues/37 | S35: =IF(G35="Done","Done",IF(I35="","End TBD",IF(I35<'Executive Summary'!$B$4,"Overdue",IF(H35>'Executive Summary'!$B$4,"Upcoming","Active window"))))
A36: P2-ROSA-01 | B36: ROSA Platform / Security | C36: Phase 2 | D36: OpenShift / ROSA | E36: Task | F36: P0 | G36: To Do | H36: 46306 | I36: 46313 | J36: =IF(OR(H36="",I36=""),"",I36-H36+1) | K36: =IF(OR(H36="",I36=""),"",NETWORKDAYS(H36,I36,'Sources & Change Log'!$J$2:$J$5)-COUNTIFS('Team Calendar'!$A$5:$A$12,L36,'Team Calendar'!$C$5:$C$12,">="&H36,'Team Calendar'!$C$5:$C$12,"<="&I36,'Team Calendar'!$F$5:$F$12,"Personal absence")) | L36: 이하영 | M36: 이권욱 | N36: D10; D12; D17; D21 | O36: RISK-07; RISK-10; RISK-11; RISK-12 | P36: ROSA Cluster Ready, Namespace/RBAC/NetworkPolicy/SecurityContext, Hybrid Route 및 Application 배포 선행조건과 G5 Evidence 확보 | Q36: 10-09는 비근무일이다. 계정·Quota·리전 전제는 G4 이전에 확인하고 Cluster 범위를 최소화한다. | R36: https://github.com/321Team/fds-project-baseline/issues/38 | S36: =IF(G36="Done","Done",IF(I36="","End TBD",IF(I36<'Executive Summary'!$B$4,"Overdue",IF(H36>'Executive Summary'!$B$4,"Upcoming","Active window"))))
A37: MS-G4-01 | B37: G4 Cloud / VPN Ready | C37: Phase 2 | D37: Milestone / Cloud & VPN | E37: Milestone | F37: P0 | G37: To Do | H37: 46308 | I37: 46308 | J37: =IF(OR(H37="",I37=""),"",I37-H37+1) | K37: =IF(OR(H37="",I37=""),"",NETWORKDAYS(H37,I37,'Sources & Change Log'!$J$2:$J$5)-COUNTIFS('Team Calendar'!$A$5:$A$12,L37,'Team Calendar'!$C$5:$C$12,">="&H37,'Team Calendar'!$C$5:$C$12,"<="&I37,'Team Calendar'!$F$5:$F$12,"Personal absence")) | L37: 이권욱 | M37: 이하영 | N37: D21 | O37: RISK-10; RISK-11; RISK-12 | P37: Terraform 인프라, 승인 Transit/VPN, Route/Security, ROSA 선행조건 및 승인 TCP 경로 준비도 승인 | Q37: 10-05 비근무를 반영한다. OCI No-Go 시 승인 Fallback 기준으로 판정한다. | R37: https://github.com/321Team/fds-project-baseline/issues/39 | S37: =IF(G37="Done","Done",IF(I37="","End TBD",IF(I37<'Executive Summary'!$B$4,"Overdue",IF(H37>'Executive Summary'!$B$4,"Upcoming","Active window"))))
A38: DEC-P2-DNS-01 | B38: Hybrid DNS Scope Decision | C38: Phase 2 | D38: Architecture / DNS | E38: Decision | F38: P1 | G38: To Do | H38: 46307 | I38: 46311 | J38: =IF(OR(H38="",I38=""),"",I38-H38+1) | K38: =IF(OR(H38="",I38=""),"",NETWORKDAYS(H38,I38,'Sources & Change Log'!$J$2:$J$5)-COUNTIFS('Team Calendar'!$A$5:$A$12,L38,'Team Calendar'!$C$5:$C$12,">="&H38,'Team Calendar'!$C$5:$C$12,"<="&I38,'Team Calendar'!$F$5:$F$12,"Personal absence")) | L38: 이권욱 | M38: 이하영 | N38: D11; D23 | O38: RISK-10; RISK-12 | P38: P0 IP Endpoint 유지 또는 Hybrid DNS P1 적용을 확정하고 Resolver/Forwarding/Zone/Route/테스트·Cancelled 결정 근거를 승인 | Q38: Hybrid P0 E2E는 IP Endpoint를 허용하므로 본 P1 결정 미완료가 G5/G6를 자동 차단하지 않는다. | R38: https://github.com/321Team/fds-project-baseline/issues/40 | S38: =IF(G38="Done","Done",IF(I38="","End TBD",IF(I38<'Executive Summary'!$B$4,"Overdue",IF(H38>'Executive Summary'!$B$4,"Upcoming","Active window"))))
A39: DEC-P2-OP-01 | B39: Operator Supply Chain Scope Decision | C39: Phase 2 | D39: Architecture / Operator Supply Chain | E39: Decision | F39: P1 | G39: To Do | H39: 46307 | I39: 46311 | J39: =IF(OR(H39="",I39=""),"",I39-H39+1) | K39: =IF(OR(H39="",I39=""),"",NETWORKDAYS(H39,I39,'Sources & Change Log'!$J$2:$J$5)-COUNTIFS('Team Calendar'!$A$5:$A$12,L39,'Team Calendar'!$C$5:$C$12,">="&H39,'Team Calendar'!$C$5:$C$12,"<="&I39,'Team Calendar'!$F$5:$F$12,"Personal absence")) | L39: 이하영 | M39: 이권욱, 이재환 | N39: D22; D26 | O39: RISK-06; RISK-11; RISK-15 | P39: ROSA Operator 공급망을 Direct Catalog 또는 oc-mirror/Harbor/Custom CatalogSource 중 하나로 결정하고 구현·N/A 기준 승인 | Q39: D26에서 Direct Catalog 선택 시 P2-OP-01은 Cancelled 처리하고, Mirror 선택 시 P2-OP-01을 활성화한다. | R39: https://github.com/321Team/fds-project-baseline/issues/41 | S39: =IF(G39="Done","Done",IF(I39="","End TBD",IF(I39<'Executive Summary'!$B$4,"Overdue",IF(H39>'Executive Summary'!$B$4,"Upcoming","Active window"))))
A40: DEC-P2-REG-01 | B40: ROSA Image Registry Source Decision | C40: Phase 2 | D40: Architecture / Registry | E40: Decision | F40: P0 | G40: To Do | H40: 46307 | I40: 46311 | J40: =IF(OR(H40="",I40=""),"",I40-H40+1) | K40: =IF(OR(H40="",I40=""),"",NETWORKDAYS(H40,I40,'Sources & Change Log'!$J$2:$J$5)-COUNTIFS('Team Calendar'!$A$5:$A$12,L40,'Team Calendar'!$C$5:$C$12,">="&H40,'Team Calendar'!$C$5:$C$12,"<="&I40,'Team Calendar'!$F$5:$F$12,"Personal absence")) | L40: 이하영 | M40: 이권욱, 이재환 | N40: D22 | O40: RISK-06; RISK-10; RISK-11; RISK-12 | P40: ROSA Image Source를 On-Prem Harbor 또는 승인 Cloud Registry로 확정하고 Route·TLS·Credential·비용·Fallback을 승인 | Q40: 기준선의 ROSA→Harbor는 Optional이다. P2-APP-01 최종 Image 경로 전 10-16까지 확정한다. | R40: https://github.com/321Team/fds-project-baseline/issues/42 | S40: =IF(G40="Done","Done",IF(I40="","End TBD",IF(I40<'Executive Summary'!$B$4,"Overdue",IF(H40>'Executive Summary'!$B$4,"Upcoming","Active window"))))
...

Sheet Phase 1 Gantt
A1: FDS v3.1.20 · Phase 1 Gantt (CANDIDATE)
A2: 계획은 유연한 목표. 색상/막대는 예정 창이며 Runtime 완료율이 아님.
A3: Bars = Lead available weekdays within plan window; weekend/holiday/Lead absence excluded. Support allocations: Fast Track Plan.
A4: WBS ID | B4: Work Item | C4: Status | D4: Start | E4: End | F4: Lead | G4: 46260 | H4: 46261 | I4: 46262 | J4: 46263 | K4: 46264 | L4: 46265 | M4: 46266 | N4: 46267 | O4: 46268 | P4: 46269 | Q4: 46270 | R4: 46271 | S4: 46272 | T4: 46273 | U4: 46274 | V4: 46275 | W4: 46276 | X4: 46277 | Y4: 46278 | Z4: 46279 | AA4: 46280 | AB4: 46281 | AC4: 46282 | AD4: 46283 | AE4: 46284 | AF4: 46285 | AG4: 46286 | AH4: 46287 | AI4: 46288
A5: =WBS!A4 | B5: =WBS!B4 | C5: =WBS!G4 | D5: =IF(WBS!H4="","",WBS!H4) | E5: =IF(WBS!I4="","",WBS!I4) | F5: =WBS!L4 | G5: =IF(AND(ISNUMBER($D5),ISNUMBER($E5),G$4>=$D5,G$4<=$E5,WEEKDAY(G$4,2)<=5,COUNTIF('Sources & Change Log'!$J$2:$J$5,G$4)=0,COUNTIFS('Team Calendar'!$A$5:$A$12,$F5,'Team Calendar'!$C$5:$C$12,G$4)=0),1,"") | H5: =IF(AND(ISNUMBER($D5),ISNUMBER($E5),H$4>=$D5,H$4<=$E5,WEEKDAY(H$4,2)<=5,COUNTIF('Sources & Change Log'!$J$2:$J$5,H$4)=0,COUNTIFS('Team Calendar'!$A$5:$A$12,$F5,'Team Calendar'!$C$5:$C$12,H$4)=0),1,"") | I5: =IF(AND(ISNUMBER($D5),ISNUMBER($E5),I$4>=$D5,I$4<=$E5,WEEKDAY(I$4,2)<=5,COUNTIF('Sources & Change Log'!$J$2:$J$5,I$4)=0,COUNTIFS('Team Calendar'!$A$5:$A$12,$F5,'Team Calendar'!$C$5:$C$12,I$4)=0),1,"") | J5: =IF(AND(ISNUMBER($D5),ISNUMBER($E5),J$4>=$D5,J$4<=$E5,WEEKDAY(J$4,2)<=5,COUNTIF('Sources & Change Log'!$J$2:$J$5,J$4)=0,COUNTIFS('Team Calendar'!$A$5:$A$12,$F5,'Team Calendar'!$C$5:$C$12,J$4)=0),1,"") | K5: =IF(AND(ISNUMBER($D5),ISNUMBER($E5),K$4>=$D5,K$4<=$E5,WEEKDAY(K$4,2)<=5,COUNTIF('Sources & Change Log'!$J$2:$J$5,K$4)=0,COUNTIFS('Team Calendar'!$A$5:$A$12,$F5,'Team Calendar'!$C$5:$C$12,K$4)=0),1,"") | L5: =IF(AND(ISNUMBER($D5),ISNUMBER($E5),L$4>=$D5,L$4<=$E5,WEEKDAY(L$4,2)<=5,COUNTIF('Sources & Change Log'!$J$2:$J$5,L$4)=0,COUNTIFS('Team Calendar'!$A$5:$A$12,$F5,'Team Calendar'!$C$5:$C$12,L$4)=0),1,"") | M5: =IF(AND(ISNUMBER($D5),ISNUMBER($E5),M$4>=$D5,M$4<=$E5,WEEKDAY(M$4,2)<=5,COUNTIF('Sources & Change Log'!$J$2:$J$5,M$4)=0,COUNTIFS('Team Calendar'!$A$5:$A$12,$F5,'Team Calendar'!$C$5:$C$12,M$4)=0),1,"") | N5: =IF(AND(ISNUMBER($D5),ISNUMBER($E5),N$4>=$D5,N$4<=$E5,WEEKDAY(N$4,2)<=5,COUNTIF('Sources & Change Log'!$J$2:$J$5,N$4)=0,COUNTIFS('Team Calendar'!$A$5:$A$12,$F5,'Team Calendar'!$C$5:$C$12,N$4)=0),1,"") | ... AI5: =IF(AND(ISNUMBER($D5),ISNUMBER($E5),AI$4>=$D5,AI$4<=$E5,WEEKDAY(AI$4,2)<=5,COUNTIF('Sources & Change Log'!$J$2:$J$5,AI$4)=0,COUNTIFS('Team Calendar'!$A$5:$A$12,$F5,'Team Calendar'!$C$5:$C$12,AI$4)=0),1,"")
A6: =WBS!A5 | B6: =WBS!B5 | C6: =WBS!G5 | D6: =IF(WBS!H5="","",WBS!H5) | E6: =IF(WBS!I5="","",WBS!I5) | F6: =WBS!L5 | G6: =IF(AND(ISNUMBER($D6),ISNUMBER($E6),G$4>=$D6,G$4<=$E6,WEEKDAY(G$4,2)<=5,COUNTIF('Sources & Change Log'!$J$2:$J$5,G$4)=0,COUNTIFS('Team Calendar'!$A$5:$A$12,$F6,'Team Calendar'!$C$5:$C$12,G$4)=0),1,"") | H6: =IF(AND(ISNUMBER($D6),ISNUMBER($E6),H$4>=$D6,H$4<=$E6,WEEKDAY(H$4,2)<=5,COUNTIF('Sources & Change Log'!$J$2:$J$5,H$4)=0,COUNTIFS('Team Calendar'!$A$5:$A$12,$F6,'Team Calendar'!$C$5:$C$12,H$4)=0),1,"") | I6: =IF(AND(ISNUMBER($D6),ISNUMBER($E6),I$4>=$D6,I$4<=$E6,WEEKDAY(I$4,2)<=5,COUNTIF('Sources & Change Log'!$J$2:$J$5,I$4)=0,COUNTIFS('Team Calendar'!$A$5:$A$12,$F6,'Team Calendar'!$C$5:$C$12,I$4)=0),1,"") | J6: =IF(AND(ISNUMBER($D6),ISNUMBER($E6),J$4>=$D6,J$4<=$E6,WEEKDAY(J$4,2)<=5,COUNTIF('Sources & Change Log'!$J$2:$J$5,J$4)=0,COUNTIFS('Team Calendar'!$A$5:$A$12,$F6,'Team Calendar'!$C$5:$C$12,J$4)=0),1,"") | K6: =IF(AND(ISNUMBER($D6),ISNUMBER($E6),K$4>=$D6,K$4<=$E6,WEEKDAY(K$4,2)<=5,COUNTIF('Sources & Change Log'!$J$2:$J$5,K$4)=0,COUNTIFS('Team Calendar'!$A$5:$A$12,$F6,'Team Calendar'!$C$5:$C$12,K$4)=0),1,"") | L6: =IF(AND(ISNUMBER($D6),ISNUMBER($E6),L$4>=$D6,L$4<=$E6,WEEKDAY(L$4,2)<=5,COUNTIF('Sources & Change Log'!$J$2:$J$5,L$4)=0,COUNTIFS('Team Calendar'!$A$5:$A$12,$F6,'Team Calendar'!$C$5:$C$12,L$4)=0),1,"") | M6: =IF(AND(ISNUMBER($D6),ISNUMBER($E6),M$4>=$D6,M$4<=$E6,WEEKDAY(M$4,2)<=5,COUNTIF('Sources & Change Log'!$J$2:$J$5,M$4)=0,COUNTIFS('Team Calendar'!$A$5:$A$12,$F6,'Team Calendar'!$C$5:$C$12,M$4)=0),1,"") | N6: =IF(AND(ISNUMBER($D6),ISNUMBER($E6),N$4>=$D6,N$4<=$E6,WEEKDAY(N$4,2)<=5,COUNTIF('Sources & Change Log'!$J$2:$J$5,N$4)=0,COUNTIFS('Team Calendar'!$A$5:$A$12,$F6,'Team Calendar'!$C$5:$C$12,N$4)=0),1,"") | ... AI6: =IF(AND(ISNUMBER($D6),ISNUMBER($E6),AI$4>=$D6,AI$4<=$E6,WEEKDAY(AI$4,2)<=5,COUNTIF('Sources & Change Log'!$J$2:$J$5,AI$4)=0,COUNTIFS('Team Calendar'!$A$5:$A$12,$F6,'Team Calendar'!$C$5:$C$12,AI$4)=0),1,"")
A7: =WBS!A7 | B7: =WBS!B7 | C7: =WBS!G7 | D7: =IF(WBS!H7="","",WBS!H7) | E7: =IF(WBS!I7="","",WBS!I7) | F7: =WBS!L7 | G7: =IF(AND(ISNUMBER($D7),ISNUMBER($E7),G$4>=$D7,G$4<=$E7,WEEKDAY(G$4,2)<=5,COUNTIF('Sources & Change Log'!$J$2:$J$5,G$4)=0,COUNTIFS('Team Calendar'!$A$5:$A$12,$F7,'Team Calendar'!$C$5:$C$12,G$4)=0),1,"") | H7: =IF(AND(ISNUMBER($D7),ISNUMBER($E7),H$4>=$D7,H$4<=$E7,WEEKDAY(H$4,2)<=5,COUNTIF('Sources & Change Log'!$J$2:$J$5,H$4)=0,COUNTIFS('Team Calendar'!$A$5:$A$12,$F7,'Team Calendar'!$C$5:$C$12,H$4)=0),1,"") | I7: =IF(AND(ISNUMBER($D7),ISNUMBER($E7),I$4>=$D7,I$4<=$E7,WEEKDAY(I$4,2)<=5,COUNTIF('Sources & Change Log'!$J$2:$J$5,I$4)=0,COUNTIFS('Team Calendar'!$A$5:$A$12,$F7,'Team Calendar'!$C$5:$C$12,I$4)=0),1,"") | J7: =IF(AND(ISNUMBER($D7),ISNUMBER($E7),J$4>=$D7,J$4<=$E7,WEEKDAY(J$4,2)<=5,COUNTIF('Sources & Change Log'!$J$2:$J$5,J$4)=0,COUNTIFS('Team Calendar'!$A$5:$A$12,$F7,'Team Calendar'!$C$5:$C$12,J$4)=0),1,"") | K7: =IF(AND(ISNUMBER($D7),ISNUMBER($E7),K$4>=$D7,K$4<=$E7,WEEKDAY(K$4,2)<=5,COUNTIF('Sources & Change Log'!$J$2:$J$5,K$4)=0,COUNTIFS('Team Calendar'!$A$5:$A$12,$F7,'Team Calendar'!$C$5:$C$12,K$4)=0),1,"") | L7: =IF(AND(ISNUMBER($D7),ISNUMBER($E7),L$4>=$D7,L$4<=$E7,WEEKDAY(L$4,2)<=5,COUNTIF('Sources & Change Log'!$J$2:$J$5,L$4)=0,COUNTIFS('Team Calendar'!$A$5:$A$12,$F7,'Team Calendar'!$C$5:$C$12,L$4)=0),1,"") | M7: =IF(AND(ISNUMBER($D7),ISNUMBER($E7),M$4>=$D7,M$4<=$E7,WEEKDAY(M$4,2)<=5,COUNTIF('Sources & Change Log'!$J$2:$J$5,M$4)=0,COUNTIFS('Team Calendar'!$A$5:$A$12,$F7,'Team Calendar'!$C$5:$C$12,M$4)=0),1,"") | N7: =IF(AND(ISNUMBER($D7),ISNUMBER($E7),N$4>=$D7,N$4<=$E7,WEEKDAY(N$4,2)<=5,COUNTIF('Sources & Change Log'!$J$2:$J$5,N$4)=0,COUNTIFS('Team Calendar'!$A$5:$A$12,$F7,'Team Calendar'!$C$5:$C$12,N$4)=0),1,"") | ... AI7: =IF(AND(ISNUMBER($D7),ISNUMBER($E7),AI$4>=$D7,AI$4<=$E7,WEEKDAY(AI$4,2)<=5,COUNTIF('Sources & Change Log'!$J$2:$J$5,AI$4)=0,COUNTIFS('Team Calendar'!$A$5:$A$12,$F7,'Team Calendar'!$C$5:$C$12,AI$4)=0),1,"")
A8: =WBS!A6 | B8: =WBS!B6 | C8: =WBS!G6 | D8: =IF(WBS!H6="","",WBS!H6) | E8: =IF(WBS!I6="","",WBS!I6) | F8: =WBS!L6 | G8: =IF(AND(ISNUMBER($D8),ISNUMBER($E8),G$4>=$D8,G$4<=$E8,WEEKDAY(G$4,2)<=5,COUNTIF('Sources & Change Log'!$J$2:$J$5,G$4)=0,COUNTIFS('Team Calendar'!$A$5:$A$12,$F8,'Team Calendar'!$C$5:$C$12,G$4)=0),1,"") | H8: =IF(AND(ISNUMBER($D8),ISNUMBER($E8),H$4>=$D8,H$4<=$E8,WEEKDAY(H$4,2)<=5,COUNTIF('Sources & Change Log'!$J$2:$J$5,H$4)=0,COUNTIFS('Team Calendar'!$A$5:$A$12,$F8,'Team Calendar'!$C$5:$C$12,H$4)=0),1,"") | I8: =IF(AND(ISNUMBER($D8),ISNUMBER($E8),I$4>=$D8,I$4<=$E8,WEEKDAY(I$4,2)<=5,COUNTIF('Sources & Change Log'!$J$2:$J$5,I$4)=0,COUNTIFS('Team Calendar'!$A$5:$A$12,$F8,'Team Calendar'!$C$5:$C$12,I$4)=0),1,"") | J8: =IF(AND(ISNUMBER($D8),ISNUMBER($E8),J$4>=$D8,J$4<=$E8,WEEKDAY(J$4,2)<=5,COUNTIF('Sources & Change Log'!$J$2:$J$5,J$4)=0,COUNTIFS('Team Calendar'!$A$5:$A$12,$F8,'Team Calendar'!$C$5:$C$12,J$4)=0),1,"") | K8: =IF(AND(ISNUMBER($D8),ISNUMBER($E8),K$4>=$D8,K$4<=$E8,WEEKDAY(K$4,2)<=5,COUNTIF('Sources & Change Log'!$J$2:$J$5,K$4)=0,COUNTIFS('Team Calendar'!$A$5:$A$12,$F8,'Team Calendar'!$C$5:$C$12,K$4)=0),1,"") | L8: =IF(AND(ISNUMBER($D8),ISNUMBER($E8),L$4>=$D8,L$4<=$E8,WEEKDAY(L$4,2)<=5,COUNTIF('Sources & Change Log'!$J$2:$J$5,L$4)=0,COUNTIFS('Team Calendar'!$A$5:$A$12,$F8,'Team Calendar'!$C$5:$C$12,L$4)=0),1,"") | M8: =IF(AND(ISNUMBER($D8),ISNUMBER($E8),M$4>=$D8,M$4<=$E8,WEEKDAY(M$4,2)<=5,COUNTIF('Sources & Change Log'!$J$2:$J$5,M$4)=0,COUNTIFS('Team Calendar'!$A$5:$A$12,$F8,'Team Calendar'!$C$5:$C$12,M$4)=0),1,"") | N8: =IF(AND(ISNUMBER($D8),ISNUMBER($E8),N$4>=$D8,N$4<=$E8,WEEKDAY(N$4,2)<=5,COUNTIF('Sources & Change Log'!$J$2:$J$5,N$4)=0,COUNTIFS('Team Calendar'!$A$5:$A$12,$F8,'Team Calendar'!$C$5:$C$12,N$4)=0),1,"") | ... AI8: =IF(AND(ISNUMBER($D8),ISNUMBER($E8),AI$4>=$D8,AI$4<=$E8,WEEKDAY(AI$4,2)<=5,COUNTIF('Sources & Change Log'!$J$2:$J$5,AI$4)=0,COUNTIFS('Team Calendar'!$A$5:$A$12,$F8,'Team Calendar'!$C$5:$C$12,AI$4)=0),1,"")
A9: =WBS!A8 | B9: =WBS!B8 | C9: =WBS!G8 | D9: =IF(WBS!H8="","",WBS!H8) | E9: =IF(WBS!I8="","",WBS!I8) | F9: =WBS!L8 | G9: =IF(AND(ISNUMBER($D9),ISNUMBER($E9),G$4>=$D9,G$4<=$E9,WEEKDAY(G$4,2)<=5,COUNTIF('Sources & Change Log'!$J$2:$J$5,G$4)=0,COUNTIFS('Team Calendar'!$A$5:$A$12,$F9,'Team Calendar'!$C$5:$C$12,G$4)=0),1,"") | H9: =IF(AND(ISNUMBER($D9),ISNUMBER($E9),H$4>=$D9,H$4<=$E9,WEEKDAY(H$4,2)<=5,COUNTIF('Sources & Change Log'!$J$2:$J$5,H$4)=0,COUNTIFS('Team Calendar'!$A$5:$A$12,$F9,'Team Calendar'!$C$5:$C$12,H$4)=0),1,"") | I9: =IF(AND(ISNUMBER($D9),ISNUMBER($E9),I$4>=$D9,I$4<=$E9,WEEKDAY(I$4,2)<=5,COUNTIF('Sources & Change Log'!$J$2:$J$5,I$4)=0,COUNTIFS('Team Calendar'!$A$5:$A$12,$F9,'Team Calendar'!$C$5:$C$12,I$4)=0),1,"") | J9: =IF(AND(ISNUMBER($D9),ISNUMBER($E9),J$4>=$D9,J$4<=$E9,WEEKDAY(J$4,2)<=5,COUNTIF('Sources & Change Log'!$J$2:$J$5,J$4)=0,COUNTIFS('Team Calendar'!$A$5:$A$12,$F9,'Team Calendar'!$C$5:$C$12,J$4)=0),1,"") | K9: =IF(AND(ISNUMBER($D9),ISNUMBER($E9),K$4>=$D9,K$4<=$E9,WEEKDAY(K$4,2)<=5,COUNTIF('Sources & Change Log'!$J$2:$J$5,K$4)=0,COUNTIFS('Team Calendar'!$A$5:$A$12,$F9,'Team Calendar'!$C$5:$C$12,K$4)=0),1,"") | L9: =IF(AND(ISNUMBER($D9),ISNUMBER($E9),L$4>=$D9,L$4<=$E9,WEEKDAY(L$4,2)<=5,COUNTIF('Sources & Change Log'!$J$2:$J$5,L$4)=0,COUNTIFS('Team Calendar'!$A$5:$A$12,$F9,'Team Calendar'!$C$5:$C$12,L$4)=0),1,"") | M9: =IF(AND(ISNUMBER($D9),ISNUMBER($E9),M$4>=$D9,M$4<=$E9,WEEKDAY(M$4,2)<=5,COUNTIF('Sources & Change Log'!$J$2:$J$5,M$4)=0,COUNTIFS('Team Calendar'!$A$5:$A$12,$F9,'Team Calendar'!$C$5:$C$12,M$4)=0),1,"") | N9: =IF(AND(ISNUMBER($D9),ISNUMBER($E9),N$4>=$D9,N$4<=$E9,WEEKDAY(N$4,2)<=5,COUNTIF('Sources & Change Log'!$J$2:$J$5,N$4)=0,COUNTIFS('Team Calendar'!$A$5:$A$12,$F9,'Team Calendar'!$C$5:$C$12,N$4)=0),1,"") | ... AI9: =IF(AND(ISNUMBER($D9),ISNUMBER($E9),AI$4>=$D9,AI$4<=$E9,WEEKDAY(AI$4,2)<=5,COUNTIF('Sources & Change Log'!$J$2:$J$5,AI$4)=0,COUNTIFS('Team Calendar'!$A$5:$A$12,$F9,'Team Calendar'!$C$5:$C$12,AI$4)=0),1,"")
A10: =WBS!A9 | B10: =WBS!B9 | C10: =WBS!G9 | D10: =IF(WBS!H9="","",WBS!H9) | E10: =IF(WBS!I9="","",WBS!I9) | F10: =WBS!L9 | G10: =IF(AND(ISNUMBER($D10),ISNUMBER($E10),G$4>=$D10,G$4<=$E10,WEEKDAY(G$4,2)<=5,COUNTIF('Sources & Change Log'!$J$2:$J$5,G$4)=0,COUNTIFS('Team Calendar'!$A$5:$A$12,$F10,'Team Calendar'!$C$5:$C$12,G$4)=0),1,"") | H10: =IF(AND(ISNUMBER($D10),ISNUMBER($E10),H$4>=$D10,H$4<=$E10,WEEKDAY(H$4,2)<=5,COUNTIF('Sources & Change Log'!$J$2:$J$5,H$4)=0,COUNTIFS('Team Calendar'!$A$5:$A$12,$F10,'Team Calendar'!$C$5:$C$12,H$4)=0),1,"") | I10: =IF(AND(ISNUMBER($D10),ISNUMBER($E10),I$4>=$D10,I$4<=$E10,WEEKDAY(I$4,2)<=5,COUNTIF('Sources & Change Log'!$J$2:$J$5,I$4)=0,COUNTIFS('Team Calendar'!$A$5:$A$12,$F10,'Team Calendar'!$C$5:$C$12,I$4)=0),1,"") | J10: =IF(AND(ISNUMBER($D10),ISNUMBER($E10),J$4>=$D10,J$4<=$E10,WEEKDAY(J$4,2)<=5,COUNTIF('Sources & Change Log'!$J$2:$J$5,J$4)=0,COUNTIFS('Team Calendar'!$A$5:$A$12,$F10,'Team Calendar'!$C$5:$C$12,J$4)=0),1,"") | K10: =IF(AND(ISNUMBER($D10),ISNUMBER($E10),K$4>=$D10,K$4<=$E10,WEEKDAY(K$4,2)<=5,COUNTIF('Sources & Change Log'!$J$2:$J$5,K$4)=0,COUNTIFS('Team Calendar'!$A$5:$A$12,$F10,'Team Calendar'!$C$5:$C$12,K$4)=0),1,"") | L10: =IF(AND(ISNUMBER($D10),ISNUMBER($E10),L$4>=$D10,L$4<=$E10,WEEKDAY(L$4,2)<=5,COUNTIF('Sources & Change Log'!$J$2:$J$5,L$4)=0,COUNTIFS('Team Calendar'!$A$5:$A$12,$F10,'Team Calendar'!$C$5:$C$12,L$4)=0),1,"") | M10: =IF(AND(ISNUMBER($D10),ISNUMBER($E10),M$4>=$D10,M$4<=$E10,WEEKDAY(M$4,2)<=5,COUNTIF('Sources & Change Log'!$J$2:$J$5,M$4)=0,COUNTIFS('Team Calendar'!$A$5:$A$12,$F10,'Team Calendar'!$C$5:$C$12,M$4)=0),1,"") | N10: =IF(AND(ISNUMBER($D10),ISNUMBER($E10),N$4>=$D10,N$4<=$E10,WEEKDAY(N$4,2)<=5,COUNTIF('Sources & Change Log'!$J$2:$J$5,N$4)=0,COUNTIFS('Team Calendar'!$A$5:$A$12,$F10,'Team Calendar'!$C$5:$C$12,N$4)=0),1,"") | ... AI10: =IF(AND(ISNUMBER($D10),ISNUMBER($E10),AI$4>=$D10,AI$4<=$E10,WEEKDAY(AI$4,2)<=5,COUNTIF('Sources & Change Log'!$J$2:$J$5,AI$4)=0,COUNTIFS('Team Calendar'!$A$5:$A$12,$F10,'Team Calendar'!$C$5:$C$12,AI$4)=0),1,"")
A11: =WBS!A10 | B11: =WBS!B10 | C11: =WBS!G10 | D11: =IF(WBS!H10="","",WBS!H10) | E11: =IF(WBS!I10="","",WBS!I10) | F11: =WBS!L10 | G11: =IF(AND(ISNUMBER($D11),ISNUMBER($E11),G$4>=$D11,G$4<=$E11,WEEKDAY(G$4,2)<=5,COUNTIF('Sources & Change Log'!$J$2:$J$5,G$4)=0,COUNTIFS('Team Calendar'!$A$5:$A$12,$F11,'Team Calendar'!$C$5:$C$12,G$4)=0),1,"") | H11: =IF(AND(ISNUMBER($D11),ISNUMBER($E11),H$4>=$D11,H$4<=$E11,WEEKDAY(H$4,2)<=5,COUNTIF('Sources & Change Log'!$J$2:$J$5,H$4)=0,COUNTIFS('Team Calendar'!$A$5:$A$12,$F11,'Team Calendar'!$C$5:$C$12,H$4)=0),1,"") | I11: =IF(AND(ISNUMBER($D11),ISNUMBER($E11),I$4>=$D11,I$4<=$E11,WEEKDAY(I$4,2)<=5,COUNTIF('Sources & Change Log'!$J$2:$J$5,I$4)=0,COUNTIFS('Team Calendar'!$A$5:$A$12,$F11,'Team Calendar'!$C$5:$C$12,I$4)=0),1,"") | J11: =IF(AND(ISNUMBER($D11),ISNUMBER($E11),J$4>=$D11,J$4<=$E11,WEEKDAY(J$4,2)<=5,COUNTIF('Sources & Change Log'!$J$2:$J$5,J$4)=0,COUNTIFS('Team Calendar'!$A$5:$A$12,$F11,'Team Calendar'!$C$5:$C$12,J$4)=0),1,"") | K11: =IF(AND(ISNUMBER($D11),ISNUMBER($E11),K$4>=$D11,K$4<=$E11,WEEKDAY(K$4,2)<=5,COUNTIF('Sources & Change Log'!$J$2:$J$5,K$4)=0,COUNTIFS('Team Calendar'!$A$5:$A$12,$F11,'Team Calendar'!$C$5:$C$12,K$4)=0),1,"") | L11: =IF(AND(ISNUMBER($D11),ISNUMBER($E11),L$4>=$D11,L$4<=$E11,WEEKDAY(L$4,2)<=5,COUNTIF('Sources & Change Log'!$J$2:$J$5,L$4)=0,COUNTIFS('Team Calendar'!$A$5:$A$12,$F11,'Team Calendar'!$C$5:$C$12,L$4)=0),1,"") | M11: =IF(AND(ISNUMBER($D11),ISNUMBER($E11),M$4>=$D11,M$4<=$E11,WEEKDAY(M$4,2)<=5,COUNTIF('Sources & Change Log'!$J$2:$J$5,M$4)=0,COUNTIFS('Team Calendar'!$A$5:$A$12,$F11,'Team Calendar'!$C$5:$C$12,M$4)=0),1,"") | N11: =IF(AND(ISNUMBER($D11),ISNUMBER($E11),N$4>=$D11,N$4<=$E11,WEEKDAY(N$4,2)<=5,COUNTIF('Sources & Change Log'!$J$2:$J$5,N$4)=0,COUNTIFS('Team Calendar'!$A$5:$A$12,$F11,'Team Calendar'!$C$5:$C$12,N$4)=0),1,"") | ... AI11: =IF(AND(ISNUMBER($D11),ISNUMBER($E11),AI$4>=$D11,AI$4<=$E11,WEEKDAY(AI$4,2)<=5,COUNTIF('Sources & Change Log'!$J$2:$J$5,AI$4)=0,COUNTIFS('Team Calendar'!$A$5:$A$12,$F11,'Team Calendar'!$C$5:$C$12,AI$4)=0),1,"")
A12: =WBS!A11 | B12: =WBS!B11 | C12: =WBS!G11 | D12: =IF(WBS!H11="","",WBS!H11) | E12: =IF(WBS!I11="","",WBS!I11) | F12: =WBS!L11 | G12: =IF(AND(ISNUMBER($D12),ISNUMBER($E12),G$4>=$D12,G$4<=$E12,WEEKDAY(G$4,2)<=5,COUNTIF('Sources & Change Log'!$J$2:$J$5,G$4)=0,COUNTIFS('Team Calendar'!$A$5:$A$12,$F12,'Team Calendar'!$C$5:$C$12,G$4)=0),1,"") | H12: =IF(AND(ISNUMBER($D12),ISNUMBER($E12),H$4>=$D12,H$4<=$E12,WEEKDAY(H$4,2)<=5,COUNTIF('Sources & Change Log'!$J$2:$J$5,H$4)=0,COUNTIFS('Team Calendar'!$A$5:$A$12,$F12,'Team Calendar'!$C$5:$C$12,H$4)=0),1,"") | I12: =IF(AND(ISNUMBER($D12),ISNUMBER($E12),I$4>=$D12,I$4<=$E12,WEEKDAY(I$4,2)<=5,COUNTIF('Sources & Change Log'!$J$2:$J$5,I$4)=0,COUNTIFS('Team Calendar'!$A$5:$A$12,$F12,'Team Calendar'!$C$5:$C$12,I$4)=0),1,"") | J12: =IF(AND(ISNUMBER($D12),ISNUMBER($E12),J$4>=$D12,J$4<=$E12,WEEKDAY(J$4,2)<=5,COUNTIF('Sources & Change Log'!$J$2:$J$5,J$4)=0,COUNTIFS('Team Calendar'!$A$5:$A$12,$F12,'Team Calendar'!$C$5:$C$12,J$4)=0),1,"") | K12: =IF(AND(ISNUMBER($D12),ISNUMBER($E12),K$4>=$D12,K$4<=$E12,WEEKDAY(K$4,2)<=5,COUNTIF('Sources & Change Log'!$J$2:$J$5,K$4)=0,COUNTIFS('Team Calendar'!$A$5:$A$12,$F12,'Team Calendar'!$C$5:$C$12,K$4)=0),1,"") | L12: =IF(AND(ISNUMBER($D12),ISNUMBER($E12),L$4>=$D12,L$4<=$E12,WEEKDAY(L$4,2)<=5,COUNTIF('Sources & Change Log'!$J$2:$J$5,L$4)=0,COUNTIFS('Team Calendar'!$A$5:$A$12,$F12,'Team Calendar'!$C$5:$C$12,L$4)=0),1,"") | M12: =IF(AND(ISNUMBER($D12),ISNUMBER($E12),M$4>=$D12,M$4<=$E12,WEEKDAY(M$4,2)<=5,COUNTIF('Sources & Change Log'!$J$2:$J$5,M$4)=0,COUNTIFS('Team Calendar'!$A$5:$A$12,$F12,'Team Calendar'!$C$5:$C$12,M$4)=0),1,"") | N12: =IF(AND(ISNUMBER($D12),ISNUMBER($E12),N$4>=$D12,N$4<=$E12,WEEKDAY(N$4,2)<=5,COUNTIF('Sources & Change Log'!$J$2:$J$5,N$4)=0,COUNTIFS('Team Calendar'!$A$5:$A$12,$F12,'Team Calendar'!$C$5:$C$12,N$4)=0),1,"") | ... AI12: =IF(AND(ISNUMBER($D12),ISNUMBER($E12),AI$4>=$D12,AI$4<=$E12,WEEKDAY(AI$4,2)<=5,COUNTIF('Sources & Change Log'!$J$2:$J$5,AI$4)=0,COUNTIFS('Team Calendar'!$A$5:$A$12,$F12,'Team Calendar'!$C$5:$C$12,AI$4)=0),1,"")
A13: =WBS!A12 | B13: =WBS!B12 | C13: =WBS!G12 | D13: =IF(WBS!H12="","",WBS!H12) | E13: =IF(WBS!I12="","",WBS!I12) | F13: =WBS!L12 | G13: =IF(AND(ISNUMBER($D13),ISNUMBER($E13),G$4>=$D13,G$4<=$E13,WEEKDAY(G$4,2)<=5,COUNTIF('Sources & Change Log'!$J$2:$J$5,G$4)=0,COUNTIFS('Team Calendar'!$A$5:$A$12,$F13,'Team Calendar'!$C$5:$C$12,G$4)=0),1,"") | H13: =IF(AND(ISNUMBER($D13),ISNUMBER($E13),H$4>=$D13,H$4<=$E13,WEEKDAY(H$4,2)<=5,COUNTIF('Sources & Change Log'!$J$2:$J$5,H$4)=0,COUNTIFS('Team Calendar'!$A$5:$A$12,$F13,'Team Calendar'!$C$5:$C$12,H$4)=0),1,"") | I13: =IF(AND(ISNUMBER($D13),ISNUMBER($E13),I$4>=$D13,I$4<=$E13,WEEKDAY(I$4,2)<=5,COUNTIF('Sources & Change Log'!$J$2:$J$5,I$4)=0,COUNTIFS('Team Calendar'!$A$5:$A$12,$F13,'Team Calendar'!$C$5:$C$12,I$4)=0),1,"") | J13: =IF(AND(ISNUMBER($D13),ISNUMBER($E13),J$4>=$D13,J$4<=$E13,WEEKDAY(J$4,2)<=5,COUNTIF('Sources & Change Log'!$J$2:$J$5,J$4)=0,COUNTIFS('Team Calendar'!$A$5:$A$12,$F13,'Team Calendar'!$C$5:$C$12,J$4)=0),1,"") | K13: =IF(AND(ISNUMBER($D13),ISNUMBER($E13),K$4>=$D13,K$4<=$E13,WEEKDAY(K$4,2)<=5,COUNTIF('Sources & Change Log'!$J$2:$J$5,K$4)=0,COUNTIFS('Team Calendar'!$A$5:$A$12,$F13,'Team Calendar'!$C$5:$C$12,K$4)=0),1,"") | L13: =IF(AND(ISNUMBER($D13),ISNUMBER($E13),L$4>=$D13,L$4<=$E13,WEEKDAY(L$4,2)<=5,COUNTIF('Sources & Change Log'!$J$2:$J$5,L$4)=0,COUNTIFS('Team Calendar'!$A$5:$A$12,$F13,'Team Calendar'!$C$5:$C$12,L$4)=0),1,"") | M13: =IF(AND(ISNUMBER($D13),ISNUMBER($E13),M$4>=$D13,M$4<=$E13,WEEKDAY(M$4,2)<=5,COUNTIF('Sources & Change Log'!$J$2:$J$5,M$4)=0,COUNTIFS('Team Calendar'!$A$5:$A$12,$F13,'Team Calendar'!$C$5:$C$12,M$4)=0),1,"") | N13: =IF(AND(ISNUMBER($D13),ISNUMBER($E13),N$4>=$D13,N$4<=$E13,WEEKDAY(N$4,2)<=5,COUNTIF('Sources & Change Log'!$J$2:$J$5,N$4)=0,COUNTIFS('Team Calendar'!$A$5:$A$12,$F13,'Team Calendar'!$C$5:$C$12,N$4)=0),1,"") | ... AI13: =IF(AND(ISNUMBER($D13),ISNUMBER($E13),AI$4>=$D13,AI$4<=$E13,WEEKDAY(AI$4,2)<=5,COUNTIF('Sources & Change Log'!$J$2:$J$5,AI$4)=0,COUNTIFS('Team Calendar'!$A$5:$A$12,$F13,'Team Calendar'!$C$5:$C$12,AI$4)=0),1,"")
